<?xml version='1.0' ?>
<robot name="jongbub" >

    <material name="red">
        <color rgba="1 0 0 1"/>
    </material>
    <material name="orange">
        <color rgba="1 0.2 0 1"/>
    </material>
    <material name="yellow">
        <color rgba="1 1 0 1"/>
    </material>
    <material name="green">
        <color rgba="0 1 0 1"/>
    </material>
    <material name="blue">
        <color rgba="0 0 1 1"/>
    </material>
    <material name="black">
        <color rgba="0 0 0 1"/>
    </material>
    <material name="purple">
        <color rgba="0.4 0 1 1"/>
    </material>
    
    <link name="base">
        <inertial>
            <origin xyz="0 0 0" rpy="0 0 0"/>
            <mass value="1"/>
            <inertia ixx="1"  ixy="0"  ixz="0" iyy="1" iyz="0" izz="1" />
        </inertial>
        <visual>
            <origin xyz="0 0 0" rpy="0 0 0" />
            <geometry>
                <box size="0.01 0.01 0.2" />
                <mesh filename="package://jongbub/meshes/axis0.stl"/>
            </geometry>
            <material name="red"/>
        </visual>
    </link>

     <joint name="joint01" type="revolute">
        <origin xyz="0 0 0.1" rpy="0 0 0"/>
        <parent link="base"/>
        <child link="link1"/>
        <axis xyz='0 0 1'/>
        <calibration rising="0.0"/>
        <dynamics damping="0.0" friction="0.0"/>
        <limit effort="30" velocity="1.0" lower="-3.14" upper="3.14" />
        <safety_controller k_velocity="10" k_position="15" soft_lower_limit="-3.14" soft_upper_limit="3.14" />
    </joint>

    <link name="link1">
        <inertial>
            <origin xyz="0 0 0" rpy="0 0 0"/>
            <mass value="1"/>
            <inertia ixx="1"  ixy="0"  ixz="0" iyy="1" iyz="0" izz="1" />
        </inertial>
        <visual>
            <origin xyz="0 0 0.03" rpy="0 0 0" />
            <geometry>
                <box size="0.01 0.01 0.06" />
                <mesh filename="package://jongbub/meshes/axis1.stl"/>
            </geometry>
            <material name="orange"/>
        </visual>
    </link>

    <joint name="joint12" type="revolute">
        <origin xyz="0 0 0.06" rpy="0 0 0"/>
        <parent link="link1"/>
        <child link="link2"/>
        <axis xyz='0 1 0'/>
        <calibration rising="0.0"/>
        <dynamics damping="0.0" friction="0.0"/>
        <limit effort="30" velocity="1.0" lower="-3.14" upper="3.14" />
        <safety_controller k_velocity="10" k_position="15" soft_lower_limit="-3.14" soft_upper_limit="3.14" />
    </joint>

    <link name="link2">
        <inertial>
            <origin xyz="0 0 0" rpy="0 0 0"/>
            <mass value="1"/>
            <inertia ixx="1"  ixy="0"  ixz="0" iyy="1" iyz="0" izz="1" />
        </inertial>
        <visual>
            <origin xyz="0.075 0 0" rpy="0 0 0" />
            <geometry>
                <box size="0.15 0.01 0.01" />
                <mesh filename="package://jongbub/meshes/axis2.stl"/>
            </geometry>
            <material name="yellow"/>
        </visual>
    </link>


    <joint name="joint23" type="revolute">
        <origin xyz="0.15 0 0" rpy="0 -1.57 0"/>
        <parent link="link2"/>
        <child link="link3"/>
        <axis xyz='0 1 0'/>
        <calibration rising="0.0"/>
        <dynamics damping="0.0" friction="0.0"/>
        <limit effort="30" velocity="1.0" lower="-3.14" upper="3.14" />
        <safety_controller k_velocity="10" k_position="15" soft_lower_limit="-3.14" soft_upper_limit="3.14" />
    </joint>

    <link name="link3">
        <inertial>
            <origin xyz="0 0 0" rpy="0 0 0"/>
            <mass value="1"/>
            <inertia ixx="1"  ixy="0"  ixz="0" iyy="1" iyz="0" izz="1" />
        </inertial>
        <visual>
            <origin xyz="0.07 0 0" rpy="0 0 0" />
            <geometry>
                <box size="0.14 0.01 0.01" />
                <mesh filename="package://jongbub/meshes/axis3.stl"/>
            </geometry>
            <material name="green"/>
        </visual>
    </link>


    <joint name="joint34" type="revolute">
        <origin xyz="0.14 0 0" rpy="1.57 0 0"/>
        <parent link="link3"/>
        <child link="link4"/>
        <axis xyz='1 0 0'/>
        <calibration rising="0.0"/>
        <dynamics damping="0.0" friction="0.0"/>
        <limit effort="30" velocity="1.0" lower="-3.14" upper="3.14" />
        <safety_controller k_velocity="10" k_position="15" soft_lower_limit="-3.14" soft_upper_limit="3.14" />
    </joint>

    <link name="link4">
        <inertial>
            <origin xyz="0 0 0" rpy="0 0 0"/>
            <mass value="1"/>
            <inertia ixx="1"  ixy="0"  ixz="0" iyy="1" iyz="0" izz="1" />
        </inertial>
        <visual>
            <origin xyz="0 0.035 0" rpy="0 0 0" />
            <geometry>
                <box size="0.01 0.07 0.01" />
                <mesh filename="package://jongbub/meshes/axis4.stl"/>
            </geometry>
            <material name="blue"/>
        </visual>
    </link>


    <joint name="joint45" type="revolute">
        <origin xyz="0.01 0.07 0" rpy="1.57 0 0"/>
        <parent link="link4"/>
        <child link="link5"/>
        <axis xyz='1 0 0'/>
        <calibration rising="0.0"/>
        <dynamics damping="0.0" friction="0.0"/>
        <limit effort="30" velocity="1.0" lower="-3.14" upper="3.14" />
        <safety_controller k_velocity="10" k_position="15" soft_lower_limit="-3.14" soft_upper_limit="3.14" />
    </joint>

    <link name="link5">
        <inertial>
            <origin xyz="0 0 0" rpy="0 0 0"/>
            <mass value="1"/>
            <inertia ixx="1"  ixy="0"  ixz="0" iyy="1" iyz="0" izz="1" />
        </inertial>
        <visual>
            <origin xyz="0 0 0.01" rpy="0 0 0" />
            <geometry>
                <box size="0.01 0.01 0.02" />
                <mesh filename="package://jongbub/meshes/axis5.stl"/>
            </geometry>
            <material name="black"/>
        </visual>
    </link>

    <joint name="joint56" type="revolute">
        <origin xyz="0 0 0.02" rpy="0 1.57 0"/>
        <parent link="link5"/>
        <child link="link6"/>
        <axis xyz='0 0 1'/>
        <calibration rising="0.0"/>
        <dynamics damping="0.0" friction="0.0"/>
        <limit effort="30" velocity="1.0" lower="-3.14" upper="3.14" />
        <safety_controller k_velocity="10" k_position="15" soft_lower_limit="-3.14" soft_upper_limit="3.14" />
    </joint>

    <link name="link6">
        <inertial>
            <origin xyz="0 0 0" rpy="0 0 0"/>
            <mass value="1"/>
            <inertia ixx="1"  ixy="0"  ixz="0" iyy="1" iyz="0" izz="1" />
        </inertial>
        <visual>
            <origin xyz="0 0 0.025" rpy="0 0 0" />
            <geometry>
                <box size="0.01 0.01 0.05" />
                <mesh filename="package://jongbub/meshes/axis6.stl"/>
            </geometry>
            <material name="purple"/>
        </visual>
    </link>

</robot>
